{
  "nbformat": 4,
  "nbformat_minor": 0,
  "metadata": {
    "colab": {
      "provenance": [],
      "authorship_tag": "ABX9TyPb73JYrjbK2xwboiqKp5mW",
      "include_colab_link": true
    },
    "kernelspec": {
      "name": "python3",
      "display_name": "Python 3"
    },
    "language_info": {
      "name": "python"
    }
  },
  "cells": [
    {
      "cell_type": "markdown",
      "metadata": {
        "id": "view-in-github",
        "colab_type": "text"
      },
      "source": [
        "<a href=\"https://colab.research.google.com/github/ashmeenkhaira/Machine-learning-/blob/main/image_classifier.ipynb\" target=\"_parent\"><img src=\"https://colab.research.google.com/assets/colab-badge.svg\" alt=\"Open In Colab\"/></a>"
      ]
    },
    {
      "cell_type": "code",
      "execution_count": 1,
      "metadata": {
        "colab": {
          "base_uri": "https://localhost:8080/"
        },
        "id": "E3MaeCE-TeLD",
        "outputId": "58ea1838-d5df-499f-ede4-5e27c5a3ccca"
      },
      "outputs": [
        {
          "output_type": "stream",
          "name": "stdout",
          "text": [
            "Requirement already satisfied: tensorflow in /usr/local/lib/python3.11/dist-packages (2.18.0)\n",
            "Collecting tensorflow-gpu\n",
            "  Downloading tensorflow-gpu-2.12.0.tar.gz (2.6 kB)\n",
            "  \u001b[1;31merror\u001b[0m: \u001b[1msubprocess-exited-with-error\u001b[0m\n",
            "  \n",
            "  \u001b[31m×\u001b[0m \u001b[32mpython setup.py egg_info\u001b[0m did not run successfully.\n",
            "  \u001b[31m│\u001b[0m exit code: \u001b[1;36m1\u001b[0m\n",
            "  \u001b[31m╰─>\u001b[0m See above for output.\n",
            "  \n",
            "  \u001b[1;35mnote\u001b[0m: This error originates from a subprocess, and is likely not a problem with pip.\n",
            "  Preparing metadata (setup.py) ... \u001b[?25l\u001b[?25herror\n",
            "\u001b[1;31merror\u001b[0m: \u001b[1mmetadata-generation-failed\u001b[0m\n",
            "\n",
            "\u001b[31m×\u001b[0m Encountered error while generating package metadata.\n",
            "\u001b[31m╰─>\u001b[0m See above for output.\n",
            "\n",
            "\u001b[1;35mnote\u001b[0m: This is an issue with the package mentioned above, not pip.\n",
            "\u001b[1;36mhint\u001b[0m: See above for details.\n"
          ]
        }
      ],
      "source": [
        "!pip install tensorflow tensorflow-gpu opencv-python matplotlib"
      ]
    },
    {
      "cell_type": "code",
      "source": [],
      "metadata": {
        "id": "-9zuhM-waB-w"
      },
      "execution_count": null,
      "outputs": []
    }
  ]
}